File: XPS/Ratio/Mo3d-1 third/mo3d1.vms
VAMAS Surface Chemical Analysis Standard Data Transfer Format 1988 May 4
Not Specified
Not Specified
Not Specified
Not Specified
3
Conversion string = c:\users\yzu\desktop\1111\mo3d1.dat
CasaRowLabel:mo3d1.dat
CasaRowLabel:mo3d2.dat
NORM
REGULAR
0
1
Data Set
d
0
0
0
0
2
mo3d1.dat
mo3d1.dat
0
0
0
0
0
0
0
5
Casa Info Follows
0
0
0
0
XPS
1
Al
1486.6
1e+037
1e+037
1e+037
1e+037
1e+037
FAT
1e+037
1e+037
1e+037
1e+037
1e+037
1e+037
1e+037
1e+037
240 - 222.1

-1
Binding Energy
eV
240
-0.1
1
Counts
d
pulse counting
1
1
1e+037
1e+037
1e+037
1e+037
0
180
0
1
22723.4
22335.6
22404.7
22533.5
22276.6
22490.8
22577
22397
22059.1
22023.3
22303.6
22008.7
21459
21825
21821.7
22161.4
22033.9
21958.8
22316.3
22130.9
22681.7
22367
22068.9
22513.5
22960.1
22819
22412.4
22959.7
23080.9
22365.9
22995
23093.9
23308.6
23619.6
23546.6
24185.1
23989.6
24147.8
24119
24584.3
25231.6
25373.9
24661.3
25589.9
26355.1
26994.3
26751.9
27162.7
27920.1
28486.3
28526.3
29135.9
29591.1
29642.3
29594
30284.7
31200.9
32238.5
33217.4
33329.8
33659.6
34922.5
36251
37113
37533.9
39599.6
40718
42350.4
43509.4
44232.2
46313.3
48169.3
50799.3
52586.5
55413.7
58851.2
61847.1
66830.3
71270.4
74255.7
77976.4
83499.3
89083.9
92648.7
97248.4
104038
109039
111548
113509
113269
108623
101641
92180.2
81347.2
70897.9
62734.4
56040
50706.1
47857.7
46462.6
45462.7
45556.1
46315.6
47587.6
50369.8
53841.5
56006.5
60226.6
65498.6
69499.8
75141.8
81621.5
88274.5
95162.8
101557
110182
118458
128303
139827
146173
150229
149576
137568
120051
98743.3
75761.2
52697.8
34561.6
22576.8
15609.1
10419.9
8003.11
6878.36
6020.09
5685.73
5405.29
5039.64
4572.45
4281.46
4254.87
4099.02
4025.61
3907.57
3780.1
3823.43
3919.47
3685.29
3823.36
3802.47
3598.57
3606.15
3458.15
3456.03
3459.89
3361.11
3481.78
3497.68
3470.14
3363.04
3460.99
3713.75
3646.8
3355.58
3369.24
3268.95
3337.63
3403.87
3418.79
3184.77
3604.08
3729.74
3455.93
3129.2
3232.29
3444.9
3334.78
3362.92
3168.41
3191.29
3121.93
mo3d2.dat
mo3d2.dat
0
0
0
0
0
0
0
5
Casa Info Follows
0
0
0
0
XPS
2
Al
1486.6
1e+037
1e+037
1e+037
1e+037
1e+037
FAT
1e+037
1e+037
1e+037
1e+037
1e+037
1e+037
1e+037
1e+037
240 - 222.1

-1
Binding Energy
eV
240
-0.1
1
Counts
d
pulse counting
1
1
1e+037
1e+037
1e+037
1e+037
0
180
0
1
19118
19030.8
18377.3
18455.5
18739.3
18620.1
18999.9
18858.5
18510
18716.8
18088.3
18454.6
18424
18980.9
19003.7
18903
18343.5
18823.9
19278.3
19375.9
18913.8
19350.2
20177
19819.7
19694.3
20029.9
20048.8
19869.5
20178.4
20333.7
21164
21623.4
22096.1
22186.6
22134.2
22393.7
22396.5
22954
23345.5
23776.2
24247
25239.7
25151.8
25677.4
26595.1
26847.3
28193.5
28421.7
29231.3
29552
30220.7
30696.3
31915.5
33312.3
33579.5
34188.6
33696.5
34600.4
36220.4
36615
37853
39444.7
39735.1
41133
42193.8
43504.6
44836.4
46493.4
48550
49859.4
52363.8
54585.8
57953
59041
62343.1
67586.5
71296.9
73264.9
75116.4
78235
80201.9
81791.3
81227.1
81636.4
79555.8
74769.3
72461.9
68056.5
63849.9
60253.9
56910.8
52709.9
48940.8
47639.9
45488.8
43850.5
43822
44656.6
46243.1
48063.9
48595.3
49420.4
52575.2
55142
57409.2
60370.1
64563.9
68289.5
73296
77737.4
83492.4
88661.8
91741.1
93820.5
93269.7
90932.3
86479.2
78817.5
69383.2
60001.6
50970
42375.9
34424.3
26384.7
20860.3
16587.8
12402.8
9270.6
7284.36
6640.03
5487.68
4836.78
4459.52
4400.29
4168.18
3984.65
4004.51
3926.57
3902.72
3889.18
3899.74
3873.45
3926.64
3757.49
3844.64
3619.83
3502.01
3507.11
3350.87
3294.97
3395.34
3528.55
3460.2
3385.64
3263.97
3390.9
3420.25
3315.17
3228.34
3373.11
3459.23
3600.89
3520.81
3429.33
3594.69
3301.26
3127.93
3360.59
3371.5
3387.83
3263.43
3311.68
3313.12
3399.61
3471.67
3380.74
3414.49
3147.25
3040.93
3198.23
end of experiment